Workbook

Sheet shRNA Data
A1: shRNA Treatment | B1: Granules Per Cell | C1: Stdev Granules Per Cell | D1: Granule Area | E1: Stdev Granule Area | F1: n (Nuclei) | G1: n (Granules) | H1: Granules per Cells SEM | I1: Granule Area SEM | K1: s^2/n Granules Per Cell | L1: t-test Granules Per Cell | M1: p-value | O1: s^2/n Granule Area | P1: t-test Granule Area | Q1: p-value
A2: NC-1 (unstressed) | B2: 0.13015873 | C2: 0.12914823 | D2: 0.1614948 | E2: 0.15153246 | F2: 39 | G2: 5 | H2: =C2/SQRT(6) -> 0.052724543 | I2: =E2/(SQRT(G2)) -> 0.067767378 | K2: =(C2^2)/6 -> 0.0027798774 | L2: =(B3-B2)/(SQRT(K3+K2)) -> 15.405183 | M2: =(_xlfn.T.DIST.2T(ABS(L2),10)) -> 2.7055521e-08 | O2: =(E2^2)/G2 -> 0.0045924175 | P2: =(D3-D2)/(SQRT(O3+O2)) -> 13.357068 | Q2: =_xlfn.T.DIST.2T(ABS(P2),10) -> 1.0602285e-07 | R2: compared to stressed
A3: NC-1 | B3: 1.7385432 | C3: 0.99534655 | D3: 1.1141795 | E3: 0.32079316 | F3: 122 | G3: 208 | H3: =C3/SQRT(F3) -> 0.090114443 | I3: =E3/(SQRT(G3)) -> 0.022243004 | K3: =(C3^2)/F3 -> 0.0081206128 | L3: =(B3-B$3)/(SQRT(K3+K$3)) -> 0 | M3: =(_xlfn.T.DIST.2T(ABS(L3),10)) -> 1 | O3: =(E3^2)/G3 -> 0.00049475122 | P3: =(D3-D$3)/(SQRT(O3+O$3)) -> 0 | Q3: =_xlfn.T.DIST.2T(ABS(P3),10) -> 1 | R3: compared to NC-1 stressed
A4: DDX6 shRNA 13.1 | B4: =Import!M11 -> 1.2333333 | C4: =Import!M12 -> 0.47336463 | D4: =Import!D11 -> 0.97309167 | E4: =Import!D12 -> 0.25801801 | F4: =SUM(Import!G2:G10) -> 78 | G4: =SUM(Import!B2:B10) -> 106 | H4: =C4/SQRT(F4) -> 0.05359799 | I4: =E4/(SQRT(G4)) -> 0.025060925 | K4: =(C4^2)/F4 -> 0.0028727445 | L4: =(B4-B$3)/(SQRT(K4+K$3)) -> -4.8184419 | M4: =(_xlfn.T.DIST.2T(ABS(L4),10)) -> 0.00070387041 | O4: =(E4^2)/G4 -> 0.00062804996 | P4: =(D4-D$3)/(SQRT(O4+O$3)) -> -4.2105433 | Q4: =_xlfn.T.DIST.2T(ABS(P4),10) -> 0.0017983718 | R4: compared to NC-1 stressed
A5: DDX6 shRNA 13.2 | B5: =Import!M24 -> 1.2982375 | C5: =Import!M25 -> 0.67935774 | D5: =Import!D24 -> 1.0479842 | E5: =Import!D25 -> 0.32411211 | F5: =SUM(Import!G15:G23) -> 76 | G5: =SUM(Import!B15:B23) -> 112 | H5: =C5/SQRT(F5) -> 0.077927677 | I5: =E5/(SQRT(G5)) -> 0.030625716 | K5: =(C5^2)/F5 -> 0.0060727228 | L5: =(B5-B$3)/(SQRT(K5+K$3)) -> -3.6958307 | M5: =(_xlfn.T.DIST.2T(ABS(L5),10)) -> 0.0041368509 | O5: =(E5^2)/G5 -> 0.00093793448 | P5: =(D5-D$3)/(SQRT(O5+O$3)) -> -1.7488459 | Q5: =_xlfn.T.DIST.2T(ABS(P5),10) -> 0.11088775 | R5: compared to NC-1 stressed
A6: DDX6 shRNA 13.3 | B6: =Import!M37 -> 1.2744672 | C6: =Import!M38 -> 0.31658855 | D6: =Import!D37 -> 0.88507889 | E6: =Import!D38 -> 0.31679283 | F6: =SUM(Import!G28:G36) -> 84 | G6: =SUM(Import!B28:B36) -> 111 | H6: =C6/SQRT(F6) -> 0.034542643 | I6: =E6/(SQRT(G6)) -> 0.030068645 | K6: =(C6^2)/F6 -> 0.0011931942 | L6: =(B6-B$3)/(SQRT(K6+K$3)) -> -4.8086756 | M6: =(_xlfn.T.DIST.2T(ABS(L6),10)) -> 0.00071426263 | O6: =(E6^2)/G6 -> 0.0009041234 | P6: =(D6-D$3)/(SQRT(O6+O$3)) -> -6.1254338 | Q6: =_xlfn.T.DIST.2T(ABS(P6),10) -> 0.00011187867 | R6: compared to NC-1 stressed
A7: DDX6 oe | B7: =Import!M48 -> 1.8068783 | C7: =Import!M49 -> 0.960936 | D7: =Import!D48 -> 1.4156094 | E7: =Import!D49 -> 0.36408222 | F7: =SUM(Import!G41:G47) -> 44 | G7: =SUM(Import!B41:B47) -> 67 | H7: =C7/SQRT(F7) -> 0.14486655 | I7: =E7/(SQRT(G7)) -> 0.044479723 | K7: =(C7^2)/F7 -> 0.020986318 | L7: =(B7-B$3)/(SQRT(K7+K$3)) -> 0.40053997 | M7: =(_xlfn.T.DIST.2T(ABS(L7),10)) -> 0.69718237 | O7: =(E7^2)/G7 -> 0.0019784458 | P7: =(D7-D$3)/(SQRT(O7+O$3)) -> 6.0611777 | Q7: =_xlfn.T.DIST.2T(ABS(P7),10) -> 0.00012178979 | R7: compared to NC-1 stressed
B11: Treatment | C11: Granules Per Cell | D11: SEM | E11: Granule Area | F11: SEM
B12: NC-1 | C12: =B3 -> 1.7385432 | D12: =H3 -> 0.090114443 | E12: =D3 -> 1.1141795 | F12: =I3 -> 0.022243004
B13: shRNA 13.1 | C13: =B4 -> 1.2333333 | D13: =H4 -> 0.05359799 | E13: =D4 -> 0.97309167 | F13: =I4 -> 0.025060925
B14: shRNA 13.2 | C14: =B5 -> 1.2982375 | D14: =H5 -> 0.077927677 | E14: =D5 -> 1.0479842 | F14: =I5 -> 0.030625716
B15: shRNA 13.3 | C15: =B6 -> 1.2744672 | D15: =H6 -> 0.034542643 | E15: =D6 -> 0.88507889 | F15: =I6 -> 0.030068645
B16: overexpression | C16: =B7 -> 1.8068783 | D16: =H7 -> 0.14486655 | E16: =D7 -> 1.4156094 | F16: =I7 -> 0.044479723

Sheet Graph Export

Sheet Import
A1: 13.1 | B1: Num_Granules | C1: Total_Area | D1: Mean_Area | E1: Area_STDEV | F1: Area_SEM | G1: Num_Nuclei | H1: Num_GranulesNF | I1: TotalAreaNF | J1: Mean_AreaNF | K1: Area_StDevNF | L1: Area_SEMNF | M1: Granules Per Cell
A2: 001.tif | B2: 12 | C2: 9.807859 | D2: 0.817322 | E2: 0.863317 | F2: 0.249218 | G2: 9 | H2: 12 | I2: 9.807859 | J2: 0.817322 | K2: 0.863317 | L2: 0.249218 | M2: =B2/G2 -> 1.3333333
A3: 002.tif | B3: 14 | C3: 11.028918 | D3: 0.78778 | E3: 0.813273 | F3: 0.217356 | G3: 12 | H3: 14 | I3: 11.028918 | J3: 0.78778 | K3: 0.813273 | L3: 0.217356 | M3: =B3/G3 -> 1.1666667
A4: 003.tif | B4: 16 | C4: 9.335191 | D4: 0.583449 | E4: 0.589383 | F4: 0.147346 | G4: 15 | H4: 16 | I4: 9.335191 | J4: 0.583449 | K4: 0.589383 | L4: 0.147346 | M4: =B4/G4 -> 1.0666667
A5: 004.tif | B5: 6 | C5: 4.844846 | D5: 0.807474 | E5: 0.798635 | F5: 0.326042 | G5: 15 | H5: 7 | I5: 6.302239 | J5: 0.90032 | K5: 0.769323 | L5: 0.290777 | M5: =B5/G5 -> 0.4
A6: 005.tif | B6: 17 | C6: 18.434048 | D6: 1.084356 | E6: 1.014039 | F6: 0.245941 | G6: 7 | H6: 17 | I6: 18.434048 | J6: 1.084356 | K6: 1.014039 | L6: 0.245941
A7: 006.tif | B7: 6 | C7: 6.144683 | D7: 1.024114 | E7: 0.946648 | F7: 0.386467 | G7: 3 | H7: 6 | I7: 6.144683 | J7: 1.024114 | K7: 0.946648 | L7: 0.386467 | M7: =B7/G7 -> 2
A8: 007.tif | B8: 8 | C8: 9.453358 | D8: 1.18167 | E8: 1.46475 | F8: 0.517867 | G8: 6 | H8: 8 | I8: 9.453358 | J8: 1.18167 | K8: 1.46475 | L8: 0.517867 | M8: =B8/G8 -> 1.3333333
A9: 008.tif | B9: 23 | C9: 33.520032 | D9: 1.457393 | E9: 1.348305 | F9: 0.281141 | G9: 8 | H9: 26 | I9: 36.198483 | J9: 1.392249 | K9: 1.281054 | L9: 0.251235
A10: 009.tif | B10: 4 | C10: 4.057066 | D10: 1.014267 | E10: 0.826465 | F10: 0.413233 | G10: 3 | H10: 4 | I10: 4.057066 | J10: 1.014267 | K10: 0.826465 | L10: 0.413233 | M10: =B10/G10 -> 1.3333333
A11: average | B11: =AVERAGE(B2:B10) -> 11.777778 | C11: =AVERAGE(C2:C10) -> 11.847333 | D11: =AVERAGE(D2:D10) -> 0.97309167 | E11: =AVERAGE(E2:E10) -> 0.96275722 | F11: =AVERAGE(F2:F10) -> 0.30940122 | G11: =AVERAGE(G2:G10) -> 8.6666667 | H11: =AVERAGE(H2:H10) -> 12.222222 | I11: =AVERAGE(I2:I10) -> 12.306872 | ... M11: =AVERAGE(M2:M10) -> 1.2333333
A12: stdev | B12: =STDEV(B2:B10) -> 6.3003527 | C12: =STDEV(C2:C10) -> 9.1665508 | D12: =STDEV(D2:D10) -> 0.25801801 | E12: =STDEV(E2:E10) -> 0.27854242 | F12: =STDEV(F2:F10) -> 0.11381847 | G12: =STDEV(G2:G10) -> 4.5552168 | H12: =STDEV(H2:H10) -> 6.9061165 | I12: =STDEV(I2:I10) -> 9.8443544 | ... M12: =STDEV(M2:M10) -> 0.47336463
B13: =SUM(B2:B10) -> 106
A14: 13.2 | B14: Num_Granules | C14: Total_Area | D14: Mean_Area | E14: Area_STDEV | F14: Area_SEM | G14: Num_Nuclei | H14: Num_GranulesNF | I14: TotalAreaNF | J14: Mean_AreaNF | K14: Area_StDevNF | L14: Area_SEMNF | M14: Granules Per Cell
A15: 005.tif | B15: 21 | C15: 8.744356 | D15: 0.416398 | E15: 0.334591 | F15: 0.073014 | G15: 11 | H15: 21 | I15: 8.744356 | J15: 0.416398 | K15: 0.334591 | L15: 0.073014 | M15: =B15/G15 -> 1.9090909
A16: 006.tif | B16: 8 | C16: 8.98069 | D16: 1.122586 | E16: 0.782133 | F16: 0.276526 | G16: 7 | H16: 8 | I16: 8.98069 | J16: 1.122586 | K16: 0.782133 | L16: 0.276526 | M16: =B16/G16 -> 1.1428571
A17: 007.tif | B17: 19 | C17: 14.692094 | D17: 0.773268 | E17: 0.871736 | F17: 0.19999 | G17: 12 | H17: 19 | I17: 14.692094 | J17: 0.773268 | K17: 0.871736 | L17: 0.19999 | M17: =B17/G17 -> 1.5833333
A18: 008.tif | B18: 4 | C18: 4.450956 | D18: 1.112739 | E18: 0.83394 | F18: 0.41697 | G18: 14 | H18: 4 | I18: 4.450956 | J18: 1.112739 | K18: 0.83394 | L18: 0.41697 | M18: =B18/G18 -> 0.28571429
A19: 009.tif | B19: 14 | C19: 15.24354 | D19: 1.088824 | E19: 0.976828 | F19: 0.261068 | G19: 6 | H19: 14 | I19: 15.24354 | J19: 1.088824 | K19: 0.976828 | L19: 0.261068
A20: 010.tif | B20: 10 | C20: 9.020079 | D20: 0.902008 | E20: 0.975394 | F20: 0.308447 | G20: 4 | H20: 10 | I20: 9.020079 | J20: 0.902008 | K20: 0.975394 | L20: 0.308447
A21: 011.tif | B21: 2 | C21: 2.245173 | D21: 1.122586 | E21: 0.473488 | F21: 0.334806 | G21: 4 | H21: 2 | I21: 2.245173 | J21: 1.122586 | K21: 0.473488 | L21: 0.334806 | M21: =B21/G21 -> 0.5
A22: 012.tif | B22: 24 | C22: 33.047364 | D22: 1.376973 | E22: 2.147976 | F22: 0.438454 | G22: 12 | H22: 26 | I22: 85.316555 | J22: 3.281406 | K22: 7.509437 | L22: 1.472722 | M22: =B22/G22 -> 2
A23: 013.tif | B23: 10 | C23: 15.164762 | D23: 1.516476 | E23: 1.496235 | F23: 0.473151 | G23: 6 | H23: 10 | I23: 15.164762 | J23: 1.516476 | K23: 1.496235 | L23: 0.473151 | M23: =B23/G23 -> 1.6666667
A24: average | B24: =AVERAGE(B15:B23) -> 12.444444 | C24: =AVERAGE(C15:C23) -> 12.398779 | D24: =AVERAGE(D15:D23) -> 1.0479842 | E24: =AVERAGE(E15:E23) -> 0.98803567 | F24: =AVERAGE(F15:F23) -> 0.30915844 | G24: =AVERAGE(G15:G23) -> 8.4444444 | H24: =AVERAGE(H15:H23) -> 12.666667 | I24: =AVERAGE(I15:I23) -> 18.206467 | ... M24: =AVERAGE(M15:M23) -> 1.2982375
A25: stdev | B25: =STDEV(B15:B23) -> 7.6175966 | C25: =STDEV(C15:C23) -> 9.0144609 | D25: =STDEV(D15:D23) -> 0.32411211 | E25: =STDEV(E15:E23) -> 0.54491167 | F25: =STDEV(F15:F23) -> 0.12597224 | G25: =STDEV(G15:G23) -> 3.8115322 | H25: =STDEV(H15:H23) -> 8.0156098 | I25: =STDEV(I15:I23) -> 25.586029 | ... M25: =STDEV(M15:M23) -> 0.67935774
B26: =SUM(B15:B23) -> 112
A27: 13.3 | B27: Num_Granules | C27: Total_Area | D27: Mean_Area | E27: Area_STDEV | F27: Area_SEM | G27: Num_Nuclei | H27: Num_GranulesNF | I27: TotalAreaNF | J27: Mean_AreaNF | K27: Area_StDevNF | L27: Area_SEMNF | M27: Granules Per Cell
A28: 009.tif | B28: 14 | C28: 12.053031 | D28: 0.860931 | E28: 0.928632 | F28: 0.248187 | G28: 10 | H28: 15 | I28: 12.840811 | J28: 0.856054 | K28: 0.895051 | L28: 0.231101 | M28: =B28/G28 -> 1.4
A29: 010.tif | B29: 22 | C29: 13.037756 | D29: 0.592625 | E29: 0.473679 | F29: 0.100989 | G29: 19 | H29: 22 | I29: 13.037756 | J29: 0.592625 | K29: 0.473679 | L29: 0.100989 | M29: =B29/G29 -> 1.1578947
A30: 011.tif | B30: 10 | C30: 10.713806 | D30: 1.071381 | E30: 1.310443 | F30: 0.414398 | G30: 10 | H30: 10 | I30: 10.713806 | J30: 1.071381 | K30: 1.310443 | L30: 0.414398 | M30: =B30/G30 -> 1
A31: 012.tif | B31: 15 | C31: 7.562686 | D31: 0.504179 | E31: 0.429477 | F31: 0.11089 | G31: 11 | H31: 16 | I31: 8.035354 | J31: 0.50221 | K31: 0.414989 | L31: 0.103747 | M31: =B31/G31 -> 1.3636364
A32: 013.tif | B32: 10 | C32: 7.444519 | D32: 0.744452 | E32: 0.882808 | F32: 0.279168 | G32: 5 | H32: 10 | I32: 7.444519 | J32: 0.744452 | K32: 0.882808 | L32: 0.279168
A33: 014.tif | B33: 9 | C33: 11.383418 | D33: 1.264824 | E33: 1.644395 | F33: 0.548132 | G33: 8 | H33: 9 | I33: 11.383418 | J33: 1.264824 | K33: 1.644395 | L33: 0.548132 | M33: =B33/G33 -> 1.125
A34: 015.tif | B34: 16 | C34: 20.797387 | D34: 1.299837 | E34: 1.142235 | F34: 0.285559 | G34: 9 | H34: 16 | I34: 20.797387 | J34: 1.299837 | K34: 1.142235 | L34: 0.285559 | M34: =B34/G34 -> 1.7777778
A35: 016.tif | B35: 11 | C35: 5.553848 | D35: 0.504895 | E35: 0.321361 | F35: 0.096894 | G35: 7 | H35: 11 | I35: 5.553848 | J35: 0.504895 | K35: 0.321361 | L35: 0.096894 | M35: =B35/G35 -> 1.5714286
A36: 017.tif | B36: 4 | C36: 4.490345 | D36: 1.122586 | E36: 0.753899 | F36: 0.376949 | G36: 5 | H36: 4 | I36: 4.490345 | J36: 1.122586 | K36: 0.753899 | L36: 0.376949 | M36: =B36/G36 -> 0.8
A37: average | B37: =AVERAGE(B28:B36) -> 12.333333 | C37: =AVERAGE(C28:C36) -> 10.337422 | D37: =AVERAGE(D28:D36) -> 0.88507889 | E37: =AVERAGE(E28:E36) -> 0.87632544 | F37: =AVERAGE(F28:F36) -> 0.27346289 | G37: =AVERAGE(G28:G36) -> 9.3333333 | H37: =AVERAGE(H28:H36) -> 12.555556 | I37: =AVERAGE(I28:I36) -> 10.477472 | ... M37: =AVERAGE(M28:M36) -> 1.2744672
A38: stdev | B38: =STDEV(B28:B36) -> 5.1234754 | C38: =STDEV(C28:C36) -> 4.9246916 | D38: =STDEV(D28:D36) -> 0.31679283 | E38: =STDEV(E28:E36) -> 0.43827021 | F38: =STDEV(F28:F36) -> 0.15579903 | G38: =STDEV(G28:G36) -> 4.2130749 | H38: =STDEV(H28:H36) -> 5.2466921 | I38: =STDEV(I28:I36) -> 4.9341688 | ... M38: =STDEV(M28:M36) -> 0.31658855
B39: =SUM(B28:B36) -> 111
A40: Filename | B40: Num_Granules | C40: Total_Area | D40: Mean_Area | E40: Area_STDEV | F40: Area_SEM | G40: Num_Nuclei | H40: Num_GranulesNF | I40: TotalAreaNF | J40: Mean_AreaNF | K40: Area_StDevNF | L40: Area_SEMNF | M40: Granules Per Cell
...
