Workbook

Sheet Summary
A1: Concentration | B1: Average Area | C1: Stdev Area | D1: # of Droplets | E1: Stdev Droplets | G1: Area Coverage | H1: Area Coverage Stdev
A2: =4000 -> 4000 | B2: ='Imported Data'!D8 -> 2.6261662 | C2: ='Imported Data'!D9 -> 0.09086895 | D2: ='Imported Data'!C8 -> 652 | E2: ='Imported Data'!C9 -> 26.673957 | G2: =B2*D2 -> 1712.2604 | H2: =SQRT(((C2/B2)^2)+((E2/D2)^2))*G2 -> 91.745251
A3: =2000 -> 2000 | B3: ='Imported Data'!D20 -> 2.2039454 | C3: ='Imported Data'!D21 -> 0.036928778 | D3: ='Imported Data'!C20 -> 959.6 | E3: ='Imported Data'!C21 -> 56.225439 | G3: =B3*D3 -> 2114.906 | H3: =SQRT(((C3/B3)^2)+((E3/D3)^2))*G3 -> 128.88519
A4: =1000 -> 1000 | B4: ='Imported Data'!D32 -> 1.8188226 | C4: ='Imported Data'!D33 -> 0.042820521 | D4: ='Imported Data'!C32 -> 1057 | E4: ='Imported Data'!C33 -> 54.373707 | G4: =B4*D4 -> 1922.4955 | H4: =SQRT(((C4/B4)^2)+((E4/D4)^2))*G4 -> 108.76134
A5: =500 -> 500 | B5: ='Imported Data'!D43 -> 2.1008148 | C5: ='Imported Data'!D44 -> 0.047652098 | D5: ='Imported Data'!C43 -> 1247.2 | E5: ='Imported Data'!C44 -> 59.187837 | G5: =B5*D5 -> 2620.1362 | H5: =SQRT(((C5/B5)^2)+((E5/D5)^2))*G5 -> 137.81593
A6: =250 -> 250 | B6: ='Imported Data'!D54 -> 2.6158434 | C6: ='Imported Data'!D55 -> 0.039845848 | D6: ='Imported Data'!C54 -> 834.8 | E6: ='Imported Data'!C55 -> 57.833381 | G6: =B6*D6 -> 2183.7061 | H6: =SQRT(((C6/B6)^2)+((E6/D6)^2))*G6 -> 154.89679
A7: =100 -> 100 | B7: ='Imported Data'!D65 -> 3.724178 | C7: ='Imported Data'!D66 -> 0.23641793 | D7: ='Imported Data'!C65 -> 474.4 | E7: ='Imported Data'!C66 -> 106.28641 | G7: =B7*D7 -> 1766.75 | H7: =SQRT(((C7/B7)^2)+((E7/D7)^2))*G7 -> 411.41233
A8: =50 -> 50 | B8: ='Imported Data'!D76 -> 4.1818446 | C8: ='Imported Data'!D77 -> 0.15035163 | D8: ='Imported Data'!C76 -> 623 | E8: ='Imported Data'!C77 -> 27.919527 | G8: =B8*D8 -> 2605.2892 | H8: =SQRT(((C8/B8)^2)+((E8/D8)^2))*G8 -> 149.68518
A9: =0 -> 0 | B9: ='Imported Data'!D98 -> 3.6793904 | C9: ='Imported Data'!D99 -> 0.18207468 | D9: ='Imported Data'!C98 -> 635.4 | E9: ='Imported Data'!C99 -> 29.159904 | G9: =B9*D9 -> 2337.8847 | H9: =SQRT(((C9/B9)^2)+((E9/D9)^2))*G9 -> 157.78315

Sheet Figure Panels

Sheet Imported Data
A1: 4 uM + 4 uM
A2: Filename | B2: Mask Method | C2: Number of Droplets | D2: Mean Area | E2: Area STDEV | F2: Area SEM | G2: Total Area | H2: Mean Circularity | I2: Circularity STDEV | J2: Circularity SEM | K2: Mean AR | L2: AR STDEV | M2: AR SEM | N2: Mean Intensity | O2: Intensity STDEV | P2: Intensity SEM
A3: 1021_Cy3.tif | B3: 8 | C3: 634 | D3: 2.669907 | E3: 1.102023 | F3: 0.043767 | G3: 1692.7209 | H3: 1.16271 | I3: 0.161087 | J3: 0.006398 | K3: 0.932086 | L3: 0.087116 | M3: 0.006398 | N3: 6312.1317 | O3: 2195.5191 | P3: 87.195201
A4: 1022_Cy3.tif | B4: 8 | C4: 679 | D4: 2.58799 | E4: 1.156558 | F4: 0.044385 | G4: 1757.2451 | H4: 1.159298 | I4: 0.12822 | J4: 0.004921 | K4: 0.938875 | L4: 0.074426 | M4: 0.004921 | N4: 6333.1244 | O4: 1424.3167 | P4: 54.66026
A5: 1023_Cy3.tif | B5: 8 | C5: 636 | D5: 2.736843 | E5: 1.050396 | F5: 0.041651 | G5: 1740.6324 | H5: 1.168815 | I5: 0.339097 | J5: 0.013446 | K5: 0.935715 | L5: 0.084965 | M5: 0.013446 | N5: 6633.5285 | O5: 1136.7879 | P5: 45.076573
A6: 1024_Cy3.tif | B6: 8 | C6: 683 | D6: 2.641027 | E6: 1.046007 | F6: 0.040024 | G6: 1803.8215 | H6: 1.168899 | I6: 0.271713 | J6: 0.010397 | K6: 0.93437 | L6: 0.082956 | M6: 0.010397 | N6: 6154.3474 | O6: 1968.6782 | P6: 75.329376
A7: 1025_Cy3.tif | B7: 8 | C7: 628 | D7: 2.495064 | E7: 1.013339 | F7: 0.040437 | G7: 1566.9004 | H7: 1.16332 | I7: 0.165391 | J7: 0.0066 | K7: 0.934369 | L7: 0.076959 | M7: 0.0066 | N7: 6590.3293 | O7: 1874.7195 | P7: 74.809453
A8: average | B8: =AVERAGE(B3:B7) -> 8 | C8: =AVERAGE(C3:C7) -> 652 | D8: =AVERAGE(D3:D7) -> 2.6261662 | E8: =AVERAGE(E3:E7) -> 1.0736646 | F8: =AVERAGE(F3:F7) -> 0.0420528 | G8: =AVERAGE(G3:G7) -> 1712.2641 | H8: =AVERAGE(H3:H7) -> 1.1646084 | I8: =AVERAGE(I3:I7) -> 0.2131016 | ... P8: =AVERAGE(P3:P7) -> 67.414173
A9: stdev | B9: =STDEV(B3:B7) -> 0 | C9: =STDEV(C3:C7) -> 26.673957 | D9: =STDEV(D3:D7) -> 0.09086895 | E9: =STDEV(E3:E7) -> 0.056171753 | F9: =STDEV(F3:F7) -> 0.0019535814 | G9: =STDEV(G3:G7) -> 90.447983 | H9: =STDEV(H3:H7) -> 0.004170401 | I9: =STDEV(I3:I7) -> 0.08873675 | ... P9: =STDEV(P3:P7) -> 17.104534
A10: sem | B10: =(B9/(SQRT(COUNT(B3:B7)))) -> 0 | C10: =(C9/(SQRT(COUNT(C3:C7)))) -> 11.928956 | D10: =(D9/(SQRT(COUNT(D3:D7)))) -> 0.04063783 | E10: =(E9/(SQRT(COUNT(E3:E7)))) -> 0.025120771 | F10: =(F9/(SQRT(COUNT(F3:F7)))) -> 0.00087366815 | G10: =(G9/(SQRT(COUNT(G3:G7)))) -> 40.449568 | H10: =(H9/(SQRT(COUNT(H3:H7)))) -> 0.00186506 | I10: =(I9/(SQRT(COUNT(I3:I7)))) -> 0.039684281 | ... P10: =(P9/(SQRT(COUNT(P3:P7)))) -> 7.6493802
A13: 4 uM + 2 uM DDX6
A14: Filename | B14: Mask Method | C14: Number of Droplets | D14: Mean Area | E14: Area STDEV | F14: Area SEM | G14: Total Area | H14: Mean Circularity | I14: Circularity STDEV | J14: Circularity SEM | K14: Mean AR | L14: AR STDEV | M14: AR SEM | N14: Mean Intensity | O14: Intensity STDEV | P14: Intensity SEM
A15: 1028_Cy3.tif | B15: 8 | C15: 1018 | D15: 2.168214 | E15: 0.881989 | F15: 0.027643 | G15: 2207.2414 | H15: 1.179873 | I15: 0.33466 | J15: 0.010489 | K15: 0.90438 | L15: 0.12361 | M15: 0.010489 | N15: 7425.3194 | O15: 1065.0231 | P15: 33.37991
A16: 1029_Cy3.tif | B16: 8 | C16: 1010 | D16: 2.20207 | E16: 0.901989 | F16: 0.028382 | G16: 2224.0907 | H16: 1.178682 | I16: 0.382574 | J16: 0.012038 | K16: 0.900467 | L16: 0.133185 | M16: 0.012038 | N16: 7321.6526 | O16: 1055.5098 | P16: 33.212501
A17: 1030_Cy3.tif | B17: 8 | C17: 950 | D17: 2.222065 | E17: 0.903651 | F17: 0.029318 | G17: 2110.9621 | H17: 1.159526 | I17: 0.178253 | J17: 0.005783 | K17: 0.909084 | L17: 0.127484 | M17: 0.005783 | N17: 7310.6866 | O17: 1117.413 | P17: 36.253664
A18: 1031_Cy3.tif | B18: 8 | C18: 939 | D18: 2.256447 | E18: 0.943584 | F18: 0.030793 | G18: 2118.8037 | H18: 1.173344 | I18: 0.291158 | J18: 0.009502 | K18: 0.909491 | L18: 0.121131 | M18: 0.009502 | N18: 6987.3904 | O18: 1152.6367 | P18: 37.614877
A19: 1032_Cy3.tif | B19: 8 | C19: 881 | D19: 2.170931 | E19: 0.876757 | F19: 0.029539 | G19: 1912.5899 | H19: 1.185551 | I19: 0.352417 | J19: 0.011873 | K19: 0.915273 | L19: 0.112217 | M19: 0.011873 | N19: 6930.9809 | O19: 1636.6374 | P19: 55.139715
A20: average | B20: =AVERAGE(B15:B19) -> 8 | C20: =AVERAGE(C15:C19) -> 959.6 | D20: =AVERAGE(D15:D19) -> 2.2039454 | E20: =AVERAGE(E15:E19) -> 0.901594 | F20: =AVERAGE(F15:F19) -> 0.029135 | G20: =AVERAGE(G15:G19) -> 2114.7376 | H20: =AVERAGE(H15:H19) -> 1.1753952 | I20: =AVERAGE(I15:I19) -> 0.3078124 | ... P20: =AVERAGE(P15:P19) -> 39.120133
A21: stdev | B21: =STDEV(B15:B19) -> 0 | C21: =STDEV(C15:C19) -> 56.225439 | D21: =STDEV(D15:D19) -> 0.036928778 | E21: =STDEV(E15:E19) -> 0.026309599 | F21: =STDEV(F15:F19) -> 0.0011977836 | G21: =STDEV(G15:G19) -> 123.90474 | H21: =STDEV(H15:H19) -> 0.009874626 | I21: =STDEV(I15:I19) -> 0.079628305 | ... P21: =STDEV(P15:P19) -> 9.1509525
A22: sem | B22: =(B21/(SQRT(COUNT(B15:B19)))) -> 0 | C22: =(C21/(SQRT(COUNT(C15:C19)))) -> 25.144781 | D22: =(D21/(SQRT(COUNT(D15:D19)))) -> 0.016515052 | E22: =(E21/(SQRT(COUNT(E15:E19)))) -> 0.01176601 | F22: =(F21/(SQRT(COUNT(F15:F19)))) -> 0.0005356651 | G22: =(G21/(SQRT(COUNT(G15:G19)))) -> 55.411882 | H22: =(H21/(SQRT(COUNT(H15:H19)))) -> 0.004416067 | I22: =(I21/(SQRT(COUNT(I15:I19)))) -> 0.035610861 | ... P22: =(P21/(SQRT(COUNT(P15:P19)))) -> 4.0924304
A25: 4 uM + 1 uM DDX6
A26: Filename | B26: Mask Method | C26: Number of Droplets | D26: Mean Area | E26: Area STDEV | F26: Area SEM | G26: Total Area | H26: Mean Circularity | I26: Circularity STDEV | J26: Circularity SEM | K26: Mean AR | L26: AR STDEV | M26: AR SEM | N26: Mean Intensity | O26: Intensity STDEV | P26: Intensity SEM
A27: 1033_Cy3.tif | B27: 8 | C27: 1028 | D27: 1.843021 | E27: 1.048965 | F27: 0.032716 | G27: 1894.6252 | H27: 1.206621 | I27: 0.499987 | J27: 0.015594 | K27: 0.842318 | L27: 0.18174 | M27: 0.015594 | N27: 5119.4097 | O27: 819.30957 | P27: 25.553564
A28: 1034_Cy3.tif | B28: 8 | C28: 1037 | D28: 1.834995 | E28: 0.927083 | F28: 0.028789 | G28: 1902.8893 | H28: 1.164822 | I28: 0.342323 | J28: 0.01063 | K28: 0.835997 | L28: 0.180401 | M28: 0.01063 | N28: 5046.5486 | O28: 756.72528 | P28: 23.498972
A29: 1035_Cy3.tif | B29: 8 | C29: 1045 | D29: 1.868299 | E29: 1.029984 | F29: 0.031862 | G29: 1952.3725 | H29: 1.186135 | I29: 0.450273 | J29: 0.013929 | K29: 0.828809 | L29: 0.181906 | M29: 0.013929 | N29: 5019.08 | O29: 797.96995 | P29: 24.684731
A30: 1036_Cy3.tif | B30: 8 | C30: 1022 | D30: 1.775145 | E30: 0.971074 | F30: 0.030376 | G30: 1814.1981 | H30: 1.229437 | I30: 0.565848 | J30: 0.0177 | K30: 0.842181 | L30: 0.17279 | M30: 0.0177 | N30: 5020.7832 | O30: 808.30651 | P30: 25.284282
A31: 1037_Cy3.tif | B31: 8 | C31: 1153 | D31: 1.772653 | E31: 0.924832 | F31: 0.027236 | G31: 2043.8691 | H31: 1.190337 | I31: 0.36666 | J31: 0.010798 | K31: 0.857106 | L31: 0.167797 | M31: 0.010798 | N31: 5079.4633 | O31: 743.85082 | P31: 21.906409
A32: average | B32: =AVERAGE(B27:B31) -> 8 | C32: =AVERAGE(C27:C31) -> 1057 | D32: =AVERAGE(D27:D31) -> 1.8188226 | E32: =AVERAGE(E27:E31) -> 0.9803876 | F32: =AVERAGE(F27:F31) -> 0.0301958 | G32: =AVERAGE(G27:G31) -> 1921.5908 | H32: =AVERAGE(H27:H31) -> 1.1954704 | I32: =AVERAGE(I27:I31) -> 0.4450182 | ... P32: =AVERAGE(P27:P31) -> 24.185592
A33: stdev | B33: =STDEV(B27:B31) -> 0 | C33: =STDEV(C27:C31) -> 54.373707 | D33: =STDEV(D27:D31) -> 0.042820521 | E33: =STDEV(E27:E31) -> 0.057396017 | F33: =STDEV(F27:F31) -> 0.0022304487 | G33: =STDEV(G27:G31) -> 84.423897 | H33: =STDEV(H27:H31) -> 0.024139655 | I33: =STDEV(I27:I31) -> 0.09264898 | ... P33: =STDEV(P27:P31) -> 1.4994773
A34: sem | B34: =(B33/(SQRT(COUNT(B27:B31)))) -> 0 | C34: =(C33/(SQRT(COUNT(C27:C31)))) -> 24.316661 | D34: =(D33/(SQRT(COUNT(D27:D31)))) -> 0.019149919 | E34: =(E33/(SQRT(COUNT(E27:E31)))) -> 0.025668279 | F34: =(F33/(SQRT(COUNT(F27:F31)))) -> 0.00099748696 | G34: =(G33/(SQRT(COUNT(G27:G31)))) -> 37.755514 | H34: =(H33/(SQRT(COUNT(H27:H31)))) -> 0.010795582 | I34: =(I33/(SQRT(COUNT(I27:I31)))) -> 0.041433884 | ... P34: =(P33/(SQRT(COUNT(P27:P31)))) -> 0.67058665
A36: 4 uM + 500 nM DDX6
A37: Filename | B37: Mask Method | C37: Number of Droplets | D37: Mean Area | E37: Area STDEV | F37: Area SEM | G37: Total Area | H37: Mean Circularity | I37: Circularity STDEV | J37: Circularity SEM | K37: Mean AR | L37: AR STDEV | M37: AR SEM | N37: Mean Intensity | O37: Intensity STDEV | P37: Intensity SEM
A38: 1038_Cy3.tif | B38: 8 | C38: 1326 | D38: 2.033073 | E38: 1.097056 | F38: 0.030127 | G38: 2695.8542 | H38: 1.178692 | I38: 0.493928 | J38: 0.013564 | K38: 0.827435 | L38: 0.174555 | M38: 0.013564 | N38: 5602.667 | O38: 843.06393 | P38: 23.152012
A39: 1039_Cy3.tif | B39: 8 | C39: 1286 | D39: 2.071577 | E39: 1.112314 | F39: 0.031017 | G39: 2664.0484 | H39: 1.186301 | I39: 0.551175 | J39: 0.01537 | K39: 0.833025 | L39: 0.172784 | M39: 0.01537 | N39: 5606.6378 | O39: 811.41463 | P39: 22.626759
A40: 1040_Cy3.tif | B40: 8 | C40: 1238 | D40: 2.133632 | E40: 1.14257 | F40: 0.032473 | G40: 2641.4362 | H40: 1.158551 | I40: 0.440086 | J40: 0.012508 | K40: 0.827902 | L40: 0.17415 | M40: 0.012508 | N40: 5904.85 | O40: 908.83565 | P40: 25.830037
A41: 1041_Cy3.tif | B41: 8 | C41: 1206 | D41: 2.148766 | E41: 1.174501 | F41: 0.03382 | G41: 2591.4122 | H41: 1.162004 | I41: 0.454149 | J41: 0.013077 | K41: 0.820483 | L41: 0.182424 | M41: 0.013077 | N41: 5463.0901 | O41: 798.15668 | P41: 22.983412
A42: 1042_Cy3.tif | B42: 8 | C42: 1180 | D42: 2.117026 | E42: 1.121497 | F42: 0.032648 | G42: 2498.0904 | H42: 1.180841 | I42: 0.506135 | J42: 0.014734 | K42: 0.831749 | L42: 0.176263 | M42: 0.014734 | N42: 5664.4889 | O42: 898.24083 | P42: 26.148802
A43: average | B43: =AVERAGE(B38:B42) -> 8 | C43: =AVERAGE(C38:C42) -> 1247.2 | D43: =AVERAGE(D38:D42) -> 2.1008148 | E43: =AVERAGE(E38:E42) -> 1.1295876 | F43: =AVERAGE(F38:F42) -> 0.032017 | G43: =AVERAGE(G38:G42) -> 2618.1683 | H43: =AVERAGE(H38:H42) -> 1.1732778 | I43: =AVERAGE(I38:I42) -> 0.4890946 | ... P43: =AVERAGE(P38:P42) -> 24.148204
A44: stdev | B44: =STDEV(B38:B42) -> 0 | C44: =STDEV(C38:C42) -> 59.187837 | D44: =STDEV(D38:D42) -> 0.047652098 | E44: =STDEV(E38:E42) -> 0.030032883 | F44: =STDEV(F38:F42) -> 0.0014516375 | G44: =STDEV(G38:G42) -> 77.162278 | H44: =STDEV(H38:H42) -> 0.012248434 | I44: =STDEV(I38:I42) -> 0.044132615 | ... P44: =STDEV(P38:P42) -> 1.6952056
A45: sem | B45: =(B44/(SQRT(COUNT(B38:B42)))) -> 0 | C45: =(C44/(SQRT(COUNT(C38:C42)))) -> 26.469605 | D45: =(D44/(SQRT(COUNT(D38:D42)))) -> 0.021310666 | E45: =(E44/(SQRT(COUNT(E38:E42)))) -> 0.013431114 | F45: =(F44/(SQRT(COUNT(F38:F42)))) -> 0.00064919204 | G45: =(G44/(SQRT(COUNT(G38:G42)))) -> 34.50802 | H45: =(H44/(SQRT(COUNT(H38:H42)))) -> 0.005477666 | I45: =(I44/(SQRT(COUNT(I38:I42)))) -> 0.019736706 | ... P45: =(P44/(SQRT(COUNT(P38:P42)))) -> 0.758119
...
